Workbook
Name APOT_ELEG: 'ΣΤΟΙΧΕΙΑ ΕΠΙΧΕΙΡΗΣΗΣ'!$A$103:$F$106
Name APOTELEG: 'ΣΤΟΙΧΕΙΑ ΕΠΙΧΕΙΡΗΣΗΣ'!$A$103:$F$106
Name ASS: 'ΣΤΟΙΧΕΙΑ ΕΠΙΧΕΙΡΗΣΗΣ'!$A$103:$A$106
Name ISTORIKO_SYM: 'ΣΤΟΙΧΕΙΑ ΕΠΙΧΕΙΡΗΣΗΣ'!$A$114:$A$117
Name ktiriaki_pol: 'ΣΤΟΙΧΕΙΑ ΕΠΙΧΕΙΡΗΣΗΣ'!$A$63:$A$66
Name metadosi: 'ΣΤΟΙΧΕΙΑ ΕΠΙΧΕΙΡΗΣΗΣ'!$A$73:$A$76
Name PLITHOS: 'ΣΤΟΙΧΕΙΑ ΕΠΙΧΕΙΡΗΣΗΣ'!$A$53:$A$57
Name Table1: #REF!

Sheet ΣΤΟΙΧΕΙΑ ΕΠΙΧΕΙΡΗΣΗΣ
D1: Έντυπο Αξιολόγησης – Κατάταξης σε κατηγορία επικινδυνότητας – Καθορισμός συχνότητας ελέγχων
A4: ΑΡΧΗΓΕΙΟ ΠΥΡΟΣΒΕΣΤΙΚΟΥ | D4: Α/Α Αξιολόγησης: | F4: Ημερομηνία:
A5: ΣΩΜΑΤΟΣ
A6: A/A ΑΙΤΗΣΗΣ
A8: ΣΤΟΙΧΕΙΑ ΕΠΙΧΕΙΡΗΣΗΣ / ΕΓΚΑΤΑΣΤΑΣΗΣ / ΟΙΚΟΝΟΜΙΚΗΣ ΔΡΑΣΤΗΡΙΟΤΗΤΑΣ
A9: ΕΠΩΝΥΜΙΑ ΕΠΙΧΕΙΡΗΣΗΣ :
A10: ΥΠΕΥΘΥΝΟΣ ΕΠΙΧΕΙΡΗΣΗΣ :
A11: ΕΙΔΟΣ ΔΡΑΣΤΗΡΙΟΤΗΤΑΣ :
A12: ΠΕΡΙΦΕΡΕΙΑ / ΠΕΡΙΦΕΡΕΙΑΚΗ ΕΝΟΤΗΤΑ :
A13: ΠΕΡΙΟΧΗ / ΔΗΜΟΣ :
A14: ΟΔΟΣ / ΑΡΙΘΜΟΣ :
A15: Τ.Κ. :
A16: ΤΗΛΕΦΩΝΑ :
A17: ΕMAIL :
A20: Τύπος Πληρότητας
A21: Κατηγορία Πληρότητας | B21: Εγρήγορση/Οικειότητα/Κινητικότητα Χρηστών | G21: Βαθμός
A22: Α | B22: Χρήστες που δεν κοιμούνται/Εξοικιωμένοι | G22: 0
A23: Β | B23: Χρήστες που δεν κοιμούνται/Μη εξοικειωμένοι | G23: 8
A24: Γ | B24: Χρήστες που κοιμούνται/Εξοικειωμένοι | G24: 4
A25: Δ | B25: Χρήστες που κοιμούνται/Εξοικειωμένοι | G25: 12
A26: Ε | B26: Χρήστες που δεν κοιμούνται/Εξοικειωμένοι/Περιορισμένης κινητικότητας-Ευαίσθητες ομάδες | G26: 12
A27: ΣΤ | B27: Χρήστες που κοιμούνται/Εξοικειωμένοι/Περιορισμένης κινητικότητας-Ευαίσθητες ομάδες | G27: 16
A28: Κατηγορία Τύπου Πληρότητας της αξιολογούμενης εγκατάστασης | G28: Βαθμός (Β1)
A29: Α | G29: =VLOOKUP(A29,A22:G27,7) -> 0
A31: Ρυθμός Ανάπτυξης Πυρκαγιάς
A32: Κατηγορία Ρυθμού | B32: Ρυθμός Ανάπτυξης | C32: Περιγραφή | G32: Βαθμός
A33: 1 | B33: Αργός | C33: Χαμηλό πυροθερμικό φορτίο ομοιόμορφα κατανεμημένο,μικρές διακριτές ποσότητες καυσίμων ή υλικών περιορισμένης καυστότητας (όπως μηχανήματα, συσκευές, μεταλλικά αντικείμενα, δομικά υλικά), που συμβάλλουν αμελητέα στην ανάπτυξη πυρκαγιάς. | G33: 0
A34: 2 | B34: Μεσαίος | C34: Χαμηλό εώς Μέτριο πυροθερμικό φορτίο ομοιόμορφα κατανεμημένο, αποτελούμενο από διάφορα είδη καυστών υλικών (όπως κουτιά από χαρτόνια, ξύλινες παλέτες, βιβλία σε ράφια, ξύλινα έπιπλα, οχήματα), που συμβάλλουν στην ανάπτυξη πυρκαγιάς. | G34: 4
A35: 3 | B35: Ταχύς | C35: Μεσαίες ποσότητες συσσωρευμένων καυστών υλικών σε ράφια ή χωρίς ( όπως πλαστικών , συνθετικών υφασμάτων,ηλεκτρικών και ηλεκτρονικών συσκευών),που συμβάλλουν ταχεία στην ανάπτυξη πυρκαγιάς. | G35: 8
A36: 4 | B36: Υπερταχύς | C36: Μεσαίες έως μεγάλες ποσότητες καυστών υλικών, πολυμερή κυτταρίνης, διογκωμένα πολυμερή, εύφλεκτα υγρά και αέρια, όπου μπορεί να εμφανιστεί ταχεία ανεξέλεγκτη ανάπτυξη πυρκαγιάς | G36: 12
A37: Κατηγορία Τύπου Πληρότητας της αξιολογούμενης εγκατάστασης | G37: Βαθμός (Β2)
A38: 1 | G38: =VLOOKUP(A38,A33:G36,7) -> 0
A41: ΑΞΙΟΛΟΓΗΣΗ ΚΙΝΔΥΝΟΥ 1ου ΕΠΙΠΕΔΟΥ
A42: Συνολική Βαθμολογία Εγγενών Κριτηρίων της εγκατάστασης (Β1 + Β2) | D42: Επίπεδο Εγγενούς Επικινδυνότητας | G42: Αξιολόγηση Κινδύνου 2ου Επιπέδου
A43: =SUM(G29,G38) -> 0 | D43: 0-8 | E43: Χαμηλό | G43: ΌΧΙ*
D44: 9-18 | E44: Μεσαίο | G44: ΝΑΙ
D45: 19-28 | E45: Υψηλό
A46: Επίπεδο Εγγενούς Επικινδυνότητας και απαίτηση για αξιολόγηση 2ου βαθμού | E46: =IF(A43<=8,E43,IF(AND(A43>=9,A43<=18),E44,E45)) -> Χαμηλό | G46: =IF(A43>8,G44,G43) -> ΌΧΙ*
A47: *Λαμβάνεται υπόψιν μόνο για οικονομικές δραστηριότητες/εγκαταστάσεις που υπάγονται σε καθεστώς άδειας, έγκρισης ή γνωστοποίησης λειτουργίας και δεν έχουν απαίτηση έκδοσης διοικητικής πράξης πυροπροστασίας (παρ.5.4.1.) και δεν πραγματοποιούνται τακτικοί έλεγχοι
A50: Β. Ειδικά κριτήρια για την κατάταξη σε επίπεδα επικινδυνότητας
...

Sheet Συχνότητα Ελέγχων Αρχικής Αξιολ
A1: Συχνότητα Ελέγχων
A2: Αρχικό Επίπεδο Επικινδυνότητας | B2: Συχνότητα ελέγχων
A3: Χαμηλό | B3: Δεν πραγματοποιούνται έλεγχοι
A4: Μεσαίο | B4: Κάθε 36 μήνες
A5: Υψηλό | B5: Κάθε 12 μήνες
A6: Καθορισμός Συχνότητας τακτικών ελέγχων της εγκατάστασης
A7: Αρχικό Επίπεδο Επικινδυνότητας της αξιολογούμενης εγκατάστασης | B7: Συχνότητα ελέγχων
A8: ='Δ2 ΑΡΧΙΚΗ ΑΞΙΟΛΟΓΗΣΗ'!B6 -> Υψηλό | B8: =IF(A8=A3,B3,IF(A8=A4,B4,B5)) -> Κάθε 12 μήνες

Sheet Β1 ΤΥΠΟΣ ΠΛΗΡΟΤΗΤΑΣ
A1: Τύπος Πληρότητας
A2: Κατηγορία Πληρότητας | B2: Εγρήγορση/Οικειότητα/Κινητικότητα Χρηστών | C2: Βαθμός
A3: Α | B3: Χρήστες που δεν κοιμούνται/Εξοικιωμένοι | C3: 0
A4: Β | B4: Χρήστες που δεν κοιμούνται/Μη εξοικειωμένοι | C4: 8
A5: Γ | B5: Χρήστες που κοιμούνται/Εξοικειωμένοι | C5: 4
A6: Δ | B6: Χρήστες που κοιμούνται/Εξοικειωμένοι | C6: 12
A7: Ε | B7: Χρήστες που δεν κοιμούνται/Εξοικειωμένοι/Περιορισμένης κινητικότητας-Ευαίσθητες ομάδες | C7: 12
A8: ΣΤ | B8: Χρήστες που κοιμούνται/Εξοικειωμένοι/Περιορισμένης κινητικότητας-Ευαίσθητες ομάδες | C8: 16
A9: Κατηγορία Τύπου Πληρότητας της αξιολογούμενης εγκατάστασης | C9: Βαθμός (Β1)
A10: ΣΤ | C10: =IF($A$10=$A$3,$C$3,IF($A$10=$A$4,$C$4,IF($A$10=$A$5,$C$5,IF($A$10=$A$6,$C$6,IF($A$10=$A$7,$C$7,$C$8))))) -> 16

Sheet B2 ΡΥΘΜΟΣ ΑΝΑΠΤΥΞΗΣ ΠΥΡΚΑΓΙΑΣ
A1: Ρυθμός Ανάπτυξης Πυρκαγιάς
A2: Κατηγορία Ρυθμού | B2: Ρυθμός Ανάπτυξης | C2: Περιγραφή | D2: Βαθμός
A3: 1 | B3: Αργός | C3: Χαμηλό πυροθερμικό φορτίο ομοιόμορφα κατανεμημένο,μικρές διακριτές ποσότητες καυσίμων ή υλικών περιορισμένης καυστότητας (όπως μηχανήματα, συσκευές, μεταλλικά αντικείμενα, δομικά υλικά), που συμβάλλουν αμελητέα στην ανάπτυξη πυρκαγιάς. | D3: 0
A4: 2 | B4: Μεσαίος | C4: Χαμηλό εώς Μέτριο πυροθερμικό φορτίο ομοιόμορφα κατανεμημένο, αποτελούμενο από διάφορα είδη καυστών υλικών (όπως κουτιά από χαρτόνια, ξύλινες παλέτες, βιβλία σε ράφια, ξύλινα έπιπλα, οχήματα), που συμβάλλουν στην ανάπτυξη πυρκαγιάς. | D4: 4
A5: 3 | B5: Ταχύς | C5: Μεσαίες ποσότητες συσσωρευμένων καυστών υλικών σε ράφια ή χωρίς ( όπως πλαστικών , συνθετικών υφασμάτων,ηλεκτρικών και ηλεκτρονικών συσκευών),που συμβάλλουν ταχεία στην ανάπτυξη πυρκαγιάς. | D5: 8
A6: 4 | B6: Υπερταχύς | C6: Μεσαίες έως μεγάλες ποσότητες καυστών υλικών, πολυμερή κυτταρίνης, διογκωμένα πολυμερή, εύφλεκτα υγρά και αέρια, όπου μπορεί να εμφανιστεί ταχεία ανεξέλεγκτη ανάπτυξη πυρκαγιάς | D6: 12
A7: Κατηγορία Τύπου Πληρότητας της αξιολογούμενης εγκατάστασης | D7: Βαθμός (Β2)
A8: 4 | D8: =IF(A8=A3,D3,IF(A8=A4,D4,IF(A8=A5,D5,D6))) -> 12

Sheet Δ1 ΕΓΓΕΝΗΣ ΑΞΙΟΛΟΓΗΣΗ
A1: ΑΞΙΟΛΟΓΗΣΗ ΚΙΝΔΥΝΟΥ 1ου ΕΠΙΠΕΔΟΥ
A2: Συνολική Βαθμολογία Εγγενών Κριτηρίων της εγκατάστασης (Β1 + Β2) | B2: Επίπεδο Εγγενούς Επικινδυνότητας | D2: Αξιολόγηση Κινδύνου 2ου Επιπέδου
A3: =SUM('Β1 ΤΥΠΟΣ ΠΛΗΡΟΤΗΤΑΣ'!C10+'B2 ΡΥΘΜΟΣ ΑΝΑΠΤΥΞΗΣ ΠΥΡΚΑΓΙΑΣ'!D8) -> 28 | B3: 0-8 | C3: Χαμηλό | D3: ΌΧΙ*
B4: 9-18 | C4: Μεσαίο | D4: ΝΑΙ
B5: 19-28 | C5: Υψηλό
A6: Επίπεδο Εγγενούς Επικινδυνότητας και απαίτηση για αξιολόγηση 2ου βαθμού | C6: =IF($A$3<=8,$C$3,IF($A$3<=18,$C$4,$C$5)) -> Υψηλό | D6: =IF($A$3<=8,$D$3,$D$4) -> ΝΑΙ
A7: *Λαμβάνεται υπόψιν μόνο για οικονομικές δραστηριότητες/εγκαταστάσεις που υπάγονται σε καθεστώς άδειας, έγκρισης ή γνωστοποίησης λειτουργίας και δεν έχουν απαίτηση έκδοσης διοικητικής πράξης πυροπροστασίας (παρ.5.4.1.) και δεν πραγματοποιούνται τακτικοί έλεγχοι

Sheet B3 ΠΛΗΘΟΣ ΧΡΗΣΤΩΝ
A1: Πλήθος Χρηστών
A2: Κατηγορία | B2: Πλήθος δυνητικών χρηστών | C2: Βαθμός
A3: Μικρό | B3: Εώς 50 άτομα | C3: 0
A4: Μεσαίο | B4: Από 51 έως 200 άτομα | C4: 2
A5: Μεγάλο | B5: Από 201 έως 500 άτομα | C5: 4
A6: Πολύ Μεγάλο | B6: Από 501 και πάνω | C6: 6
A7: Κατηγορία Πλήθους Χρηστών της αξιολογούμενης εγκατάστασης | C7: Βαθμός (Β3)
A8: Πολύ Μεγάλο | C8: =IF($A$8=$A$3,$C$3,IF($A$8=$A$4,$C$4,IF($A$8=$A$5,$C$5,$C$6))) -> 6

Sheet Β4 ΚΤΙΡΙΑΚΗ ΠΟΛΥΠΛΟΚΟΤΗΤΑ
A1: Κτηριακή πολυπλοκότητα
A2: Κατηγορία | B2: Περιγραφή | C2: Βαθμός
A3: Χαμηλή | B3: Κτίριο με απλή διαρρύθμιση, καλή οπτική πρόσβαση, κατάλληλα σχεδιασμένη και με μικρή απόσταση από όδευση διαφυγής, καλό επίπεδο παροχής εξόδου με τελικές εξόδους που οδηγούν απευθείας στο εξωτερικό του κτιρίου | C3: 0
A4: Μεσαία | B4: Κτίριο πολλαπλών πυροδιαμερισμάτων, με τα περισσότερα χαρακτηριστικά του σχεδιασμένα μη σύνθετα και πολύπλοκα με αποτέλεσμα η διαχείριση της εκκένωσης να μην παρουσιάζει ιδιαίτερες απαιτήσεις. | C4: 4
A5: Υψηλή | B5: Μεγάλο σύνθετο κτίριο όπως μεγάλα κτιριακά συγκροτήματα( κτίρια πολλαπλών χρήσεων, νοσοκομεία, εμπορικά κέντρα, αεροδρόμια, κλπ.) με σύνθετη και πολύπλοκη εσωτερική διαρρύθμιση με αποτέλεσμα η διαχείριση της εκκένωσης να παρουσιάζει ιδιαίτερες απαιτήσεις. | C5: 6
A6: Κατηγορία Κτιριακής Πολυπλοκότητας της αξιολογούμενης εγκατάστασης | C6: Βαθμός (Β4)
A7: Χαμηλή | C7: =IF($A$7=$A$3,$C$3,IF($A$7=$A$4,$C$4,$C$5)) -> 0

Sheet Β5 ΜΕΤΑΔΟΣΗ ΠΥΡΚΑΓΙΑΣ
A1: Μετάδοση πυρκαγίας
A2: Κατηγορία | B2: Κίνδυνος μετάδοσης | C2: Παράμετρος Μετάδοσης | D2: Βαθμός
A3: 1 | B3: Μικρός | C3: Απόσταση από γειτονικά κτίρια μεγαλύτερη των 15μ, ή μεγαλύτερη από το διπλάσιο ύψος του κτιρίου | D3: 0
A4: 2 | B4: Μέτριος | C4: (1) Απόσταση από γειτονικά κτίρια μικρότερη των 15μ ή μικρότερη από το διπλάσιο ύψος τους κτιρίου. (2) Η εγκατάσταση καταλαμβάνει μέρος του κτιρίου. | D4: 4
A5: 3 | B5: Μεγάλος | C5: Αποθήκευση / επεξεργασία / παραγωγή μεγάλων ποσοτήτων επικίνδυνων , εύφλεκτων, εκρηκτικών υλών. | D5: 6
A6: Κατηγορία Μετάδοσης πυρκαγιάς της αξιολογούμενης εγκατάστασης | C6: Βαθμός (Β5)
A7: 1 | C7: =IF($A$7=$A$3,$D$3,IF($A$7=$A$4,$D$4,$D$5)) -> 0

Sheet Δ2 ΑΡΧΙΚΗ ΑΞΙΟΛΟΓΗΣΗ
A1: ΑΞΙΟΛΟΓΗΣΗ ΚΙΝΔΥΝΟΥ 2ου ΕΠΙΠΕΔΟΥ
A2: Συνολική Βαθμολογία Εγγενών και Ειδικών Κριτηρίων της εγκατάστασης (Β1 + Β2 + Β3 + Β4 + Β5) | B2: Επίπεδο Αρχικής Επικινδυνότητας
A3: =SUM('Β1 ΤΥΠΟΣ ΠΛΗΡΟΤΗΤΑΣ'!C10+'B2 ΡΥΘΜΟΣ ΑΝΑΠΤΥΞΗΣ ΠΥΡΚΑΓΙΑΣ'!D8,'B3 ΠΛΗΘΟΣ ΧΡΗΣΤΩΝ'!C8+'Β4 ΚΤΙΡΙΑΚΗ ΠΟΛΥΠΛΟΚΟΤΗΤΑ'!C7+'Β5 ΜΕΤΑΔΟΣΗ ΠΥΡΚΑΓΙΑΣ'!C7) -> 34 | B3: 0-14 | C3: Χαμηλό
B4: 15-30 | C4: Μεσαίο
B5: 31-46 | C5: Υψηλό
A6: Κατάταξη Αξιολογούμενης Εγκατάστασης Σε Αρχικό Επίπεδο Επικινδυνότητας | B6: =IF($A$3<=14,$C$3,IF($A$3<=30,$C$4,C$5)) -> Υψηλό

Sheet Γ1 ΑΠΟΤΕΛΕΣΜΑ ΕΛΕΓΧΟΥ
A1: Αποτέλεσμα Ελέγχου
A2: Κατηγορία Επικινδυνότητας | B2: Βαθμός
A3: -
A4: Χαμηλή | B4: 0
A5: Μεσαία | B5: 6
A6: Υψηλή | B6: 12
A7: Κατηγορία Επικινδυνότητας της αξιολογούμενης εγκατάστασης | B7: Βαθμός (Β6)
A8: Υψηλή | B8: =IF($A$8=$A$4,$B$4,IF($A$8=$A$5,$B$5,IF($A$8=$A$3,"-",$B$6))) -> 12

Sheet Γ2 ΙΣΤΟΡΙΚΟ ΣΥΜΜΟΡΦΩΣΗΣ
A1: Ιστορικό Συμμόρφωσης
A2: Ιστορικό Συμμόρφωσης | B2: Βαθμός
A3: -
A4: Πλήρης Συμμόρφωση | B4: 0
A5: Μερική Συμμόρφωση | B5: 3
A6: Χαμηλή Συμμόρφωση | B6: 6
A7: Ιστορικό Συμμόρφωσης της αξιολογούμενης εγκατάστασης | B7: Βαθμός (Β7)
A8: Χαμηλή Συμμόρφωση | B8: =IF($A$8=$A$4,$B$4,IF($A$8=$A$5,$B$5,IF($A$8="-","-",$B$6))) -> 6

Sheet Δ3 ΤΕΛΙΚΟ ΕΠΙΠΕΔΟ ΧΩΡΙΣ ΙΣΤΟΡΙΚ
A1: ΑΞΙΟΛΟΓΗΣΗ ΚΙΝΔΥΝΟΥ 3ου ΕΠΙΠΕΔΟΥ
A2: Συνολική Βαθμολογία(Β1 + Β2 + Β3 + Β4 + Β5 + Β6) | B2: Ορια συνολικής Βαθμολογίας κριτηρίων ( Χωρίς Ιστορικό Συμμόρφωσης) | C2: Τελικό επίπεδο επικνδυνότητας
A3: =IF('Γ2 ΙΣΤΟΡΙΚΟ ΣΥΜΜΟΡΦΩΣΗΣ'!B8="-",'Δ2 ΑΡΧΙΚΗ ΑΞΙΟΛΟΓΗΣΗ'!A3:A5+'Γ1 ΑΠΟΤΕΛΕΣΜΑ ΕΛΕΓΧΟΥ'!B8,"-") -> - | B3: 0-19 | C3: Χαμηλό
B4: 20-39 | C4: Μεσαίο
B5: 40-58 | C5: Υψηλό
A7: Κατάταξη Αξιολογούμενης Εγκατάστασης Σε Τελικό Επίπεδο Επικινδυνότητας | B7: =IF($A$3<=19,$C$3,IF($A$3<=39,$C$4,IF($A$3="-","-",C$5))) -> -

Sheet Δ3 ΤΕΛΙΚΟ ΕΠΙΠΕΔΟ ΜΕ ΙΣΤΟΡΙΚΟ
A1: ΑΞΙΟΛΟΓΗΣΗ ΚΙΝΔΥΝΟΥ 3ου ΕΠΙΠΕΔΟΥ
A2: Συνολική Βαθμολογία(Β1 + Β2 + Β3 + Β4 + Β5 + Β6 + Β7) | B2: Ορια συνολικής Βαθμολογίας κριτηρίων | C2: Τελικό επίπεδο επικνδυνότητας
A3: =IF('Γ2 ΙΣΤΟΡΙΚΟ ΣΥΜΜΟΡΦΩΣΗΣ'!B8<>"-",SUM('Β1 ΤΥΠΟΣ ΠΛΗΡΟΤΗΤΑΣ'!C10+'B2 ΡΥΘΜΟΣ ΑΝΑΠΤΥΞΗΣ ΠΥΡΚΑΓΙΑΣ'!D8,'B3 ΠΛΗΘΟΣ ΧΡΗΣΤΩΝ'!C8+'Β4 ΚΤΙΡΙΑΚΗ ΠΟΛΥΠΛΟΚΟΤΗΤΑ'!C7+'Β5 ΜΕΤΑΔΟΣΗ ΠΥΡΚΑΓΙΑΣ'!C7+'Γ1 ΑΠΟΤΕΛΕΣΜΑ ΕΛΕΓΧΟΥ'!B8+'Γ2 ΙΣΤΟΡΙΚΟ ΣΥΜΜΟΡΦΩΣΗΣ'!B8),"-") -> 52 | B3: 0-21 | C3: Χαμηλό
B4: 22-43 | C4: Μεσαίο
B5: 44-64 | C5: Υψηλό
A7: Κατάταξη Αξιολογούμενης Εγκατάστασης Σε Αρχικό Επίπεδο Επικινδυνότητας | B7: =IF(A3="-","-",IF($A$3<=21,$C$3,IF($A$3<=43,$C$4,$C$5))) -> Υψηλό

Sheet Συχνότητα Ελέγχων Τελικής Αξιολ
A1: Συχνότητα Ελέγχων
A2: Τελικό Επίπεδο Επικινδυνότητας | B2: Συχνότητα ελέγχων
A3: Χαμηλό | B3: Δεν πραγματοποιούνται έλεγχοι.
A4: Μεσαίο | B4: Κάθε 36 μήνες
A5: Υψηλό | B5: Κάθε 12 μήνες
A6: Καθορισμός Συχνότητας τακτικών ελέγχων της εγκατάστασης
A7: Τελικό Επίπεδο Επικινδυνότητας της αξιολογούμενης εγκατάστασης | B7: Συχνότητα ελέγχων
A8: =IF('Δ3 ΤΕΛΙΚΟ ΕΠΙΠΕΔΟ ΧΩΡΙΣ ΙΣΤΟΡΙΚ'!A3<>"-",'Δ3 ΤΕΛΙΚΟ ΕΠΙΠΕΔΟ ΧΩΡΙΣ ΙΣΤΟΡΙΚ'!B7,'Δ3 ΤΕΛΙΚΟ ΕΠΙΠΕΔΟ ΜΕ ΙΣΤΟΡΙΚΟ'!B7) -> Υψηλό | B8: =IF(A8=A3,B3,IF(A8=A4,B4,B5)) -> Κάθε 12 μήνες
A9: \
